<?xml version='1.0' encoding='utf-8'?>
<sdf version="1.9" xmlns:drake="http://drake.mit.edu">
  <model name="robotiq_epick_2cup_model">
    <link name="robotiq_epick_2cup_base_link">
      <inertial>
        <pose>0 0 0.081 0 -0 0</pose>
        <mass>1.12</mass>
        <inertia>
          <ixx>0.003084</ixx>
          <ixy>0</ixy>
          <ixz>0</ixz>
          <iyy>0.002999</iyy>
          <iyz>0</iyz>
          <izz>0.000546</izz>
        </inertia>
      </inertial>
      <collision name="robotiq_epick_2cup_base_collision">
        <pose>0 0 0.0095 0 0 0</pose>
        <geometry>
          <cylinder>
            <radius>0.038</radius>
            <length>0.019</length>
          </cylinder>
        </geometry>
      </collision>
      <collision name="robotiq_epick_2cup_body_collision">
        <pose>0 0 0.079 0 0 0</pose>
        <geometry>
          <box>
            <size>0.083 0.048 0.12</size>
          </box>
        </geometry>
      </collision>
      <collision name="robotiq_epick_2cup_bracket_collision">
        <pose>0 0 0.125 0 0 0</pose>
        <geometry>
          <box>
            <size>0.05 0.24 0.03</size>
          </box>
        </geometry>
      </collision>
      <visual name="robotiq_epick_2cup_visual">
        <pose degrees="True">0 0 0.101 -90 0 90</pose>
        <geometry>
          <mesh>
            <scale>1 1 1</scale>
            <uri>../meshes/visual/robotiq_epick_2cup.obj</uri>
          </mesh>
        </geometry>
      </visual>
    </link>
    <frame name="suction_cup_0" attached_to="robotiq_epick_2cup_base_link">
      <pose degrees="True">0 0.0955 0.14783 180 0 0</pose>
    </frame>
    <frame name="suction_cup_1" attached_to="robotiq_epick_2cup_base_link">
      <pose degrees="True">0 -0.0955 0.14783 180 0 0</pose>
    </frame>
    <!--**BELOW AUTOGENERATED** by gen_suction_cup_spring_model.py-->
    <!--modifying by hand not recommended.-->
    <link name="cup_0_link">
      <pose relative_to="suction_cup_0">0 0 -0.01 0 0 0</pose>
      <inertial>
        <mass>0.01</mass>
        <inertia>
          <ixx>4e-06</ixx>
          <ixy>0</ixy>
          <ixz>0</ixz>
          <iyy>4e-06</iyy>
          <iyz>0</iyz>
          <izz>3.5e-06</izz>
        </inertia>
      </inertial>
    </link>
    <joint name="base_to_cup_0_body_joint" type="prismatic">
      <parent>suction_cup_0</parent>
      <child>cup_0_link</child>
      <axis>
        <xyz>0 0 1</xyz>
        <limit>
          <effort>0</effort>
          <lower>0</lower>
          <upper>0.005</upper>
        </limit>
        <dynamics>
          <spring_reference>0</spring_reference>
          <spring_stiffness>700</spring_stiffness>
          <damping>1.0</damping>
        </dynamics>
      </axis>
    </joint>
    <link name="cup_0_edge_pt_0_body">
      <pose relative_to="suction_cup_0">0 0 0 0 0 0</pose>
      <inertial>
        <mass>0.0025</mass>
        <inertia>
          <ixx>1e-06</ixx>
          <ixy>0</ixy>
          <ixz>0</ixz>
          <iyy>1e-06</iyy>
          <iyz>0</iyz>
          <izz>8.75e-07</izz>
        </inertia>
      </inertial>
      <collision name="cup_0_edge_pt_0_collision">
        <pose>0.026 0.0 -0.036 0 0 0</pose>
        <geometry>
          <sphere>
            <radius>0.001</radius>
          </sphere>
        </geometry>
        <drake:proximity_properties>
          <drake:mu_dynamic>0.6</drake:mu_dynamic>
          <drake:mu_static>0.6</drake:mu_static>
        </drake:proximity_properties>
      </collision>
    </link>
    <joint name="cup_0_body_to_edge_pt_0_joint" type="prismatic">
      <parent>cup_0_link</parent>
      <child>cup_0_edge_pt_0_body</child>
      <axis>
        <xyz>0 0 1</xyz>
        <limit>
          <effort>0</effort>
          <lower>0</lower>
          <upper>0.005</upper>
        </limit>
        <dynamics>
          <spring_reference>0</spring_reference>
          <spring_stiffness>175.0</spring_stiffness>
          <damping>0.25</damping>
        </dynamics>
      </axis>
    </joint>
    <link name="cup_0_edge_pt_1_body">
      <pose relative_to="suction_cup_0">0 0 0 0 0 0</pose>
      <inertial>
        <mass>0.0025</mass>
        <inertia>
          <ixx>1e-06</ixx>
          <ixy>0</ixy>
          <ixz>0</ixz>
          <iyy>1e-06</iyy>
          <iyz>0</iyz>
          <izz>8.75e-07</izz>
        </inertia>
      </inertial>
      <collision name="cup_0_edge_pt_1_collision">
        <pose>1.5920408388915591e-18 0.026 -0.036 0 0 0</pose>
        <geometry>
          <sphere>
            <radius>0.001</radius>
          </sphere>
        </geometry>
        <drake:proximity_properties>
          <drake:mu_dynamic>0.6</drake:mu_dynamic>
          <drake:mu_static>0.6</drake:mu_static>
        </drake:proximity_properties>
      </collision>
    </link>
    <joint name="cup_0_body_to_edge_pt_1_joint" type="prismatic">
      <parent>cup_0_link</parent>
      <child>cup_0_edge_pt_1_body</child>
      <axis>
        <xyz>0 0 1</xyz>
        <limit>
          <effort>0</effort>
          <lower>0</lower>
          <upper>0.005</upper>
        </limit>
        <dynamics>
          <spring_reference>0</spring_reference>
          <spring_stiffness>175.0</spring_stiffness>
          <damping>0.25</damping>
        </dynamics>
      </axis>
    </joint>
    <link name="cup_0_edge_pt_2_body">
      <pose relative_to="suction_cup_0">0 0 0 0 0 0</pose>
      <inertial>
        <mass>0.0025</mass>
        <inertia>
          <ixx>1e-06</ixx>
          <ixy>0</ixy>
          <ixz>0</ixz>
          <iyy>1e-06</iyy>
          <iyz>0</iyz>
          <izz>8.75e-07</izz>
        </inertia>
      </inertial>
      <collision name="cup_0_edge_pt_2_collision">
        <pose>-0.026 3.1840816777831182e-18 -0.036 0 0 0</pose>
        <geometry>
          <sphere>
            <radius>0.001</radius>
          </sphere>
        </geometry>
        <drake:proximity_properties>
          <drake:mu_dynamic>0.6</drake:mu_dynamic>
          <drake:mu_static>0.6</drake:mu_static>
        </drake:proximity_properties>
      </collision>
    </link>
    <joint name="cup_0_body_to_edge_pt_2_joint" type="prismatic">
      <parent>cup_0_link</parent>
      <child>cup_0_edge_pt_2_body</child>
      <axis>
        <xyz>0 0 1</xyz>
        <limit>
          <effort>0</effort>
          <lower>0</lower>
          <upper>0.005</upper>
        </limit>
        <dynamics>
          <spring_reference>0</spring_reference>
          <spring_stiffness>175.0</spring_stiffness>
          <damping>0.25</damping>
        </dynamics>
      </axis>
    </joint>
    <link name="cup_0_edge_pt_3_body">
      <pose relative_to="suction_cup_0">0 0 0 0 0 0</pose>
      <inertial>
        <mass>0.0025</mass>
        <inertia>
          <ixx>1e-06</ixx>
          <ixy>0</ixy>
          <ixz>0</ixz>
          <iyy>1e-06</iyy>
          <iyz>0</iyz>
          <izz>8.75e-07</izz>
        </inertia>
      </inertial>
      <collision name="cup_0_edge_pt_3_collision">
        <pose>-4.776122516674677e-18 -0.026 -0.036 0 0 0</pose>
        <geometry>
          <sphere>
            <radius>0.001</radius>
          </sphere>
        </geometry>
        <drake:proximity_properties>
          <drake:mu_dynamic>0.6</drake:mu_dynamic>
          <drake:mu_static>0.6</drake:mu_static>
        </drake:proximity_properties>
      </collision>
    </link>
    <joint name="cup_0_body_to_edge_pt_3_joint" type="prismatic">
      <parent>cup_0_link</parent>
      <child>cup_0_edge_pt_3_body</child>
      <axis>
        <xyz>0 0 1</xyz>
        <limit>
          <effort>0</effort>
          <lower>0</lower>
          <upper>0.005</upper>
        </limit>
        <dynamics>
          <spring_reference>0</spring_reference>
          <spring_stiffness>175.0</spring_stiffness>
          <damping>0.25</damping>
        </dynamics>
      </axis>
    </joint>
    <link name="cup_1_link">
      <pose relative_to="suction_cup_1">0 0 -0.01 0 0 0</pose>
      <inertial>
        <mass>0.01</mass>
        <inertia>
          <ixx>4e-06</ixx>
          <ixy>0</ixy>
          <ixz>0</ixz>
          <iyy>4e-06</iyy>
          <iyz>0</iyz>
          <izz>3.5e-06</izz>
        </inertia>
      </inertial>
    </link>
    <joint name="base_to_cup_1_body_joint" type="prismatic">
      <parent>suction_cup_1</parent>
      <child>cup_1_link</child>
      <axis>
        <xyz>0 0 1</xyz>
        <limit>
          <effort>0</effort>
          <lower>0</lower>
          <upper>0.005</upper>
        </limit>
        <dynamics>
          <spring_reference>0</spring_reference>
          <spring_stiffness>700</spring_stiffness>
          <damping>1.0</damping>
        </dynamics>
      </axis>
    </joint>
    <link name="cup_1_edge_pt_0_body">
      <pose relative_to="suction_cup_1">0 0 0 0 0 0</pose>
      <inertial>
        <mass>0.0025</mass>
        <inertia>
          <ixx>1e-06</ixx>
          <ixy>0</ixy>
          <ixz>0</ixz>
          <iyy>1e-06</iyy>
          <iyz>0</iyz>
          <izz>8.75e-07</izz>
        </inertia>
      </inertial>
      <collision name="cup_1_edge_pt_0_collision">
        <pose>0.026 0.0 -0.036 0 0 0</pose>
        <geometry>
          <sphere>
            <radius>0.001</radius>
          </sphere>
        </geometry>
        <drake:proximity_properties>
          <drake:mu_dynamic>0.6</drake:mu_dynamic>
          <drake:mu_static>0.6</drake:mu_static>
        </drake:proximity_properties>
      </collision>
    </link>
    <joint name="cup_1_body_to_edge_pt_0_joint" type="prismatic">
      <parent>cup_1_link</parent>
      <child>cup_1_edge_pt_0_body</child>
      <axis>
        <xyz>0 0 1</xyz>
        <limit>
          <effort>0</effort>
          <lower>0</lower>
          <upper>0.005</upper>
        </limit>
        <dynamics>
          <spring_reference>0</spring_reference>
          <spring_stiffness>175.0</spring_stiffness>
          <damping>0.25</damping>
        </dynamics>
      </axis>
    </joint>
    <link name="cup_1_edge_pt_1_body">
      <pose relative_to="suction_cup_1">0 0 0 0 0 0</pose>
      <inertial>
        <mass>0.0025</mass>
        <inertia>
          <ixx>1e-06</ixx>
          <ixy>0</ixy>
          <ixz>0</ixz>
          <iyy>1e-06</iyy>
          <iyz>0</iyz>
          <izz>8.75e-07</izz>
        </inertia>
      </inertial>
      <collision name="cup_1_edge_pt_1_collision">
        <pose>1.5920408388915591e-18 0.026 -0.036 0 0 0</pose>
        <geometry>
          <sphere>
            <radius>0.001</radius>
          </sphere>
        </geometry>
        <drake:proximity_properties>
          <drake:mu_dynamic>0.6</drake:mu_dynamic>
          <drake:mu_static>0.6</drake:mu_static>
        </drake:proximity_properties>
      </collision>
    </link>
    <joint name="cup_1_body_to_edge_pt_1_joint" type="prismatic">
      <parent>cup_1_link</parent>
      <child>cup_1_edge_pt_1_body</child>
      <axis>
        <xyz>0 0 1</xyz>
        <limit>
          <effort>0</effort>
          <lower>0</lower>
          <upper>0.005</upper>
        </limit>
        <dynamics>
          <spring_reference>0</spring_reference>
          <spring_stiffness>175.0</spring_stiffness>
          <damping>0.25</damping>
        </dynamics>
      </axis>
    </joint>
    <link name="cup_1_edge_pt_2_body">
      <pose relative_to="suction_cup_1">0 0 0 0 0 0</pose>
      <inertial>
        <mass>0.0025</mass>
        <inertia>
          <ixx>1e-06</ixx>
          <ixy>0</ixy>
          <ixz>0</ixz>
          <iyy>1e-06</iyy>
          <iyz>0</iyz>
          <izz>8.75e-07</izz>
        </inertia>
      </inertial>
      <collision name="cup_1_edge_pt_2_collision">
        <pose>-0.026 3.1840816777831182e-18 -0.036 0 0 0</pose>
        <geometry>
          <sphere>
            <radius>0.001</radius>
          </sphere>
        </geometry>
        <drake:proximity_properties>
          <drake:mu_dynamic>0.6</drake:mu_dynamic>
          <drake:mu_static>0.6</drake:mu_static>
        </drake:proximity_properties>
      </collision>
    </link>
    <joint name="cup_1_body_to_edge_pt_2_joint" type="prismatic">
      <parent>cup_1_link</parent>
      <child>cup_1_edge_pt_2_body</child>
      <axis>
        <xyz>0 0 1</xyz>
        <limit>
          <effort>0</effort>
          <lower>0</lower>
          <upper>0.005</upper>
        </limit>
        <dynamics>
          <spring_reference>0</spring_reference>
          <spring_stiffness>175.0</spring_stiffness>
          <damping>0.25</damping>
        </dynamics>
      </axis>
    </joint>
    <link name="cup_1_edge_pt_3_body">
      <pose relative_to="suction_cup_1">0 0 0 0 0 0</pose>
      <inertial>
        <mass>0.0025</mass>
        <inertia>
          <ixx>1e-06</ixx>
          <ixy>0</ixy>
          <ixz>0</ixz>
          <iyy>1e-06</iyy>
          <iyz>0</iyz>
          <izz>8.75e-07</izz>
        </inertia>
      </inertial>
      <collision name="cup_1_edge_pt_3_collision">
        <pose>-4.776122516674677e-18 -0.026 -0.036 0 0 0</pose>
        <geometry>
          <sphere>
            <radius>0.001</radius>
          </sphere>
        </geometry>
        <drake:proximity_properties>
          <drake:mu_dynamic>0.6</drake:mu_dynamic>
          <drake:mu_static>0.6</drake:mu_static>
        </drake:proximity_properties>
      </collision>
    </link>
    <joint name="cup_1_body_to_edge_pt_3_joint" type="prismatic">
      <parent>cup_1_link</parent>
      <child>cup_1_edge_pt_3_body</child>
      <axis>
        <xyz>0 0 1</xyz>
        <limit>
          <effort>0</effort>
          <lower>0</lower>
          <upper>0.005</upper>
        </limit>
        <dynamics>
          <spring_reference>0</spring_reference>
          <spring_stiffness>175.0</spring_stiffness>
          <damping>0.25</damping>
        </dynamics>
      </axis>
    </joint>
  </model>
</sdf>
