<?xml version="1.0"?>
<!-- Auto-generated from gz sdf -p robotiq_2f_85.urdf -->
<!-- Mesh colors added by hand -->
<sdf xmlns:drake="http://drake.mit.edu" version="1.9">
  <model name='robotiq_arg2f_85_model'>
    <link name='robotiq_arg2f_base_link'>
      <inertial>
        <pose>0 -5e-06 0.03145 0 -0 0</pose>
        <mass>0.22652</mass>
        <inertia>
          <ixx>0.00020005</ixx>
          <ixy>-4.2442e-10</ixy>
          <ixz>-2.9069e-10</ixz>
          <iyy>0.00017832</iyy>
          <iyz>-3.4402e-08</iyz>
          <izz>0.00013478</izz>
        </inertia>
      </inertial>
      <collision name='robotiq_arg2f_base_link_collision'>
        <pose>0 0 0 0 -0 0</pose>
        <geometry>
          <mesh>
            <scale>1 1 1</scale>
            <uri>../meshes/collision/robotiq_arg2f_base_link.obj</uri>
          </mesh>
        </geometry>
      </collision>
      <visual name='robotiq_arg2f_base_link_visual'>
        <pose>0 0 0 0 -0 0</pose>
        <geometry>
          <mesh>
            <scale>1 1 1</scale>
            <uri>../meshes/visual/robotiq_arg2f_85_base_link.obj</uri>
          </mesh>
        </geometry>
        <material>
          <diffuse>0.1 0.1 0.1 1.0</diffuse>
        </material>
      </visual>
    </link>
    <joint name='finger_joint' type='revolute'>
      <pose relative_to='robotiq_arg2f_base_link'>0 -0.030601 0.054904 0 -0 3.14159</pose>
      <parent>robotiq_arg2f_base_link</parent>
      <child>left_outer_knuckle</child>
      <axis>
        <xyz>1 0 0</xyz>
        <limit>
          <lower>0</lower>
          <upper>0.8</upper>
          <effort>1000</effort>
          <velocity>2</velocity>
        </limit>
        <dynamics>
          <spring_reference>0</spring_reference>
          <spring_stiffness>0</spring_stiffness>
        </dynamics>
      </axis>
    </joint>
    <link name='left_outer_knuckle'>
      <pose relative_to='finger_joint'>0 0 0 0 -0 0</pose>
      <inertial>
        <pose>0.000164 0.055483 -0.010075 0 -0 0</pose>
        <mass>0.0311462</mass>
        <inertia>
          <ixx>5.1136e-05</ixx>
          <ixy>-1.50984e-07</ixy>
          <ixz>1.67498e-07</ixz>
          <iyy>2.6195e-05</iyy>
          <iyz>2.19801e-05</iyz>
          <izz>2.77118e-05</izz>
        </inertia>
      </inertial>
      <collision name='left_outer_knuckle_collision'>
        <pose>0 0 0 0 -0 0</pose>
        <geometry>
          <mesh>
            <scale>0.001 0.001 0.001</scale>
            <uri>../meshes/collision/robotiq_arg2f_85_outer_knuckle.obj</uri>
          </mesh>
        </geometry>
      </collision>
      <collision name='left_outer_knuckle_fixed_joint_lump__left_outer_finger_collision_1'>
        <pose>0 0.0315 -0.0041 0 -0 0</pose>
        <geometry>
          <mesh>
            <scale>0.001 0.001 0.001</scale>
            <uri>../meshes/collision/robotiq_arg2f_85_outer_finger.obj</uri>
          </mesh>
        </geometry>
      </collision>
      <visual name='left_outer_knuckle_visual'>
        <pose>0 0 0 0 -0 0</pose>
        <geometry>
          <mesh>
            <scale>0.001 0.001 0.001</scale>
            <uri>../meshes/visual/robotiq_arg2f_85_outer_knuckle.obj</uri>
          </mesh>
        </geometry>
        <material>
          <diffuse>0.792156862745098 0.819607843137255 0.933333333333333 1</diffuse>
        </material>
      </visual>
      <visual name='left_outer_knuckle_fixed_joint_lump__left_outer_finger_visual_1'>
        <pose>0 0.0315 -0.0041 0 -0 0</pose>
        <geometry>
          <mesh>
            <scale>0.001 0.001 0.001</scale>
            <uri>../meshes/visual/robotiq_arg2f_85_outer_finger.obj</uri>
          </mesh>
        </geometry>
        <material>
          <diffuse>0.1 0.1 0.1 1.0</diffuse>
        </material>
      </visual>
    </link>
    <joint name='left_inner_finger_joint' type='revolute'>
      <pose relative_to='left_outer_knuckle'>0 0.0376 0.043 0 -0 0</pose>
      <parent>left_outer_knuckle</parent>
      <child>left_inner_finger</child>
      <axis>
        <xyz>1 0 0</xyz>
        <limit>
          <lower>-0.8757</lower>
          <upper>0</upper>
          <effort>0</effort>
          <!-- <effort>1000</effort>
          <velocity>2</velocity> -->
        </limit>
        <dynamics>
          <spring_reference>0</spring_reference>
          <spring_stiffness>0</spring_stiffness>
        </dynamics>
      </axis>
    </joint>
    <frame name='left_inner_finger_pad' attached_to='left_inner_finger'>
      <pose>0 -0.02202 0.03242 0 -0 0</pose>
    </frame>
    <frame name='left_inner_finger_bushing' attached_to='left_inner_finger'>
      <pose>0.0, -0.016, 0.007 0 0 0</pose>
    </frame>
    <link name='left_inner_finger'>
      <pose relative_to='left_inner_finger_joint'>0 0 0 0 -0 0</pose>
      <inertial>
        <pose>0.0003 0.016008 -0.013695 0 -0 0</pose>
        <mass>0.0104003</mass>
        <inertia>
          <ixx>2.71909e-06</ixx>
          <ixy>1.35402e-21</ixy>
          <ixz>-7.18173e-22</ixz>
          <iyy>7.691e-07</iyy>
          <iyz>6.74715e-07</iyz>
          <izz>2.30315e-06</izz>
        </inertia>
      </inertial>
      <collision name='left_inner_finger_collision'>
        <pose>0 0 0 0 -0 0</pose>
        <geometry>
          <mesh>
            <scale>0.001 0.001 0.001</scale>
            <uri>../meshes/collision/robotiq_arg2f_85_inner_finger.obj</uri>
          </mesh>
        </geometry>
      </collision>
      <collision name='left_inner_finger_pad_collision_1'>
        <pose>0 -0.02202 0.03242 0 -0 0</pose>
        <geometry>
          <box>
            <size>0.022 0.00635 0.0375</size>
          </box>
        </geometry>
      </collision>
      <visual name='left_inner_finger_visual'>
        <pose>0 0 0 0 -0 0</pose>
        <geometry>
          <mesh>
            <scale>0.001 0.001 0.001</scale>
            <uri>../meshes/visual/robotiq_arg2f_85_inner_finger.obj</uri>
          </mesh>
        </geometry>
        <material>
          <diffuse>0.1 0.1 0.1 1.0</diffuse>
        </material>
      </visual>
      <visual name='left_inner_finger_pad'>
        <pose>0 -0.02202 0.03242 0 -0 0</pose>
        <geometry>
          <box>
            <size>0.022 0.00635 0.0375</size>
          </box>
        </geometry>
        <material>
          <diffuse>0.9 0.9 0.9 1.0</diffuse>
        </material>
      </visual>
    </link>
    <joint name='left_inner_knuckle_joint' type='revolute'>
      <pose relative_to='robotiq_arg2f_base_link'>0 -0.0127 0.06142 0 -0 3.14159</pose>
      <parent>robotiq_arg2f_base_link</parent>
      <child>left_inner_knuckle</child>
      <axis>
        <xyz>1 0 0</xyz>
        <limit>
          <lower>0</lower>
          <upper>0.8757</upper>
          <effort>0</effort>
          <!-- <effort>1000</effort>
          <velocity>2</velocity> -->
        </limit>
        <dynamics>
          <spring_reference>0</spring_reference>
          <spring_stiffness>0</spring_stiffness>
        </dynamics>
      </axis>
    </joint>
    <frame name='left_inner_knuckle_bushing' attached_to='left_inner_knuckle'>
      <pose>0.0, 0.038, 0.043 0 0 0</pose>
    </frame>
    <link name='left_inner_knuckle'>
      <pose relative_to='left_inner_knuckle_joint'>0 0 0 0 -0 0</pose>
      <inertial>
        <pose>0.000123 0.050785 0.00104 0 -0 0</pose>
        <mass>0.0271177</mass>
        <inertia>
          <ixx>2.6191e-05</ixx>
          <ixy>-2.43617e-07</ixy>
          <ixz>-6.3779e-09</ixz>
          <iyy>2.82702e-06</iyy>
          <iyz>-5.37201e-07</iyz>
          <izz>2.83696e-05</izz>
        </inertia>
      </inertial>
      <collision name='left_inner_knuckle_collision'>
        <pose>0 0 0 0 -0 0</pose>
        <geometry>
          <mesh>
            <scale>0.001 0.001 0.001</scale>
            <uri>../meshes/collision/robotiq_arg2f_85_inner_knuckle.obj</uri>
          </mesh>
        </geometry>
      </collision>
      <visual name='left_inner_knuckle_visual'>
        <pose>0 0 0 0 -0 0</pose>
        <geometry>
          <mesh>
            <scale>0.001 0.001 0.001</scale>
            <uri>../meshes/visual/robotiq_arg2f_85_inner_knuckle.obj</uri>
          </mesh>
        </geometry>
        <material>
          <diffuse>0.1 0.1 0.1 1.0</diffuse>
        </material>
      </visual>
    </link>
    <joint name='right_inner_knuckle_joint' type='revolute'>
      <pose relative_to='robotiq_arg2f_base_link'>0 0.0127 0.06142 0 -0 0</pose>
      <parent>robotiq_arg2f_base_link</parent>
      <child>right_inner_knuckle</child>
      <axis>
        <xyz>1 0 0</xyz>
        <limit>
          <lower>0</lower>
          <upper>0.8757</upper>
          <effort>0</effort>
          <!-- <effort>1000</effort> -->
          <!-- <velocity>2</velocity> -->
        </limit>
        <dynamics>
          <spring_reference>0</spring_reference>
          <spring_stiffness>0</spring_stiffness>
        </dynamics>
      </axis>
    </joint>
    <frame name='right_inner_knuckle_bushing' attached_to='right_inner_knuckle'>
      <pose>0.0, 0.038, 0.043 0 -0 0</pose>
    </frame>
    <link name='right_inner_knuckle'>
      <pose relative_to='right_inner_knuckle_joint'>0 0 0 0 -0 0</pose>
      <inertial>
        <pose>0.000123 0.050785 0.00104 0 -0 0</pose>
        <mass>0.0271177</mass>
        <inertia>
          <ixx>2.6191e-05</ixx>
          <ixy>-2.43617e-07</ixy>
          <ixz>-6.3779e-09</ixz>
          <iyy>2.82702e-06</iyy>
          <iyz>-5.37201e-07</iyz>
          <izz>2.83696e-05</izz>
        </inertia>
      </inertial>
      <collision name='right_inner_knuckle_collision'>
        <pose>0 0 0 0 -0 0</pose>
        <geometry>
          <mesh>
            <scale>0.001 0.001 0.001</scale>
            <uri>../meshes/collision/robotiq_arg2f_85_inner_knuckle.obj</uri>
          </mesh>
        </geometry>
      </collision>
      <visual name='right_inner_knuckle_visual'>
        <pose>0 0 0 0 -0 0</pose>
        <geometry>
          <mesh>
            <scale>0.001 0.001 0.001</scale>
            <uri>../meshes/visual/robotiq_arg2f_85_inner_knuckle.obj</uri>
          </mesh>
        </geometry>
        <material>
          <diffuse>0.1 0.1 0.1 1.0</diffuse>
        </material>
      </visual>
    </link>
    <joint name='right_outer_knuckle_joint' type='revolute'>
      <pose relative_to='robotiq_arg2f_base_link'>0 0.030601 0.054904 0 -0 0</pose>
      <parent>robotiq_arg2f_base_link</parent>
      <child>right_outer_knuckle</child>
      <axis>
        <xyz>1 0 0</xyz>
        <limit>
          <lower>0</lower>
          <upper>0.81</upper>
          <effort>1000</effort>
          <velocity>2</velocity>
        </limit>
        <dynamics>
          <spring_reference>0</spring_reference>
          <spring_stiffness>0</spring_stiffness>
        </dynamics>
      </axis>
    </joint>
    <link name='right_outer_knuckle'>
      <pose relative_to='right_outer_knuckle_joint'>0 0 0 0 -0 0</pose>
      <inertial>
        <pose>0.000164 0.055483 -0.010075 0 -0 0</pose>
        <mass>0.0311462</mass>
        <inertia>
          <ixx>5.1136e-05</ixx>
          <ixy>-1.50984e-07</ixy>
          <ixz>1.67498e-07</ixz>
          <iyy>2.6195e-05</iyy>
          <iyz>2.19801e-05</iyz>
          <izz>2.77118e-05</izz>
        </inertia>
      </inertial>
      <collision name='right_outer_knuckle_collision'>
        <pose>0 0 0 0 -0 0</pose>
        <geometry>
          <mesh>
            <scale>0.001 0.001 0.001</scale>
            <uri>../meshes/collision/robotiq_arg2f_85_outer_knuckle.obj</uri>
          </mesh>
        </geometry>
      </collision>
      <collision name='right_outer_knuckle_fixed_joint_lump__right_outer_finger_collision_1'>
        <pose>0 0.0315 -0.0041 0 -0 0</pose>
        <geometry>
          <mesh>
            <scale>0.001 0.001 0.001</scale>
            <uri>../meshes/collision/robotiq_arg2f_85_outer_finger.obj</uri>
          </mesh>
        </geometry>
      </collision>
      <visual name='right_outer_knuckle_visual'>
        <pose>0 0 0 0 -0 0</pose>
        <geometry>
          <mesh>
            <scale>0.001 0.001 0.001</scale>
            <uri>../meshes/visual/robotiq_arg2f_85_outer_knuckle.obj</uri>
          </mesh>
        </geometry>
        <material>
          <diffuse>0.792156862745098 0.819607843137255 0.933333333333333 1</diffuse>
        </material>
      </visual>
      <visual name='right_outer_knuckle_fixed_joint_lump__right_outer_finger_visual_1'>
        <pose>0 0.0315 -0.0041 0 -0 0</pose>
        <geometry>
          <mesh>
            <scale>0.001 0.001 0.001</scale>
            <uri>../meshes/visual/robotiq_arg2f_85_outer_finger.obj</uri>
          </mesh>
        </geometry>
        <material>
          <diffuse>0.1 0.1 0.1 1.0</diffuse>
        </material>
      </visual>
    </link>
    <joint name='right_inner_finger_joint' type='revolute'>
      <pose relative_to='right_outer_knuckle'>0 0.0376 0.043 0 -0 0</pose>
      <parent>right_outer_knuckle</parent>
      <child>right_inner_finger</child>
      <axis>
        <xyz>1 0 0</xyz>
        <limit>
          <lower>-0.8757</lower>
          <upper>0</upper>
          <effort>0</effort>
          <!-- <effort>1000</effort> -->
          <!-- <velocity>2</velocity> -->
        </limit>
        <dynamics>
          <spring_reference>0</spring_reference>
          <spring_stiffness>0</spring_stiffness>
        </dynamics>
      </axis>
    </joint>
    <frame name='right_inner_finger_pad' attached_to='right_inner_finger'>
      <pose>0 -0.02202 0.03242 0 -0 0</pose>
    </frame>
    <frame name='right_inner_finger_bushing' attached_to='right_inner_finger'>
      <pose>0.0, -0.016, 0.007 0 -0 0</pose>
    </frame>
    <link name='right_inner_finger'>
      <pose relative_to='right_inner_finger_joint'>0 0 0 0 -0 0</pose>
      <inertial>
        <pose>0.0003 0.016008 -0.013695 0 -0 0</pose>
        <mass>0.0104003</mass>
        <inertia>
          <ixx>2.71909e-06</ixx>
          <ixy>1.35402e-21</ixy>
          <ixz>-7.18173e-22</ixz>
          <iyy>7.691e-07</iyy>
          <iyz>6.74715e-07</iyz>
          <izz>2.30315e-06</izz>
        </inertia>
      </inertial>
      <collision name='right_inner_finger_collision'>
        <pose>0 0 0 0 -0 0</pose>
        <geometry>
          <mesh>
            <scale>0.001 0.001 0.001</scale>
            <uri>../meshes/collision/robotiq_arg2f_85_inner_finger.obj</uri>
          </mesh>
        </geometry>
      </collision>
      <collision name='right_inner_finger_pad_collision_1'>
        <pose>0 -0.02202 0.03242 0 -0 0</pose>
        <geometry>
          <box>
            <size>0.022 0.00635 0.0375</size>
          </box>
        </geometry>
      </collision>
      <visual name='right_inner_finger_visual'>
        <pose>0 0 0 0 -0 0</pose>
        <geometry>
          <mesh>
            <scale>0.001 0.001 0.001</scale>
            <uri>../meshes/visual/robotiq_arg2f_85_inner_finger.obj</uri>
          </mesh>
        </geometry>
        <material>
          <diffuse>0.1 0.1 0.1 1.0</diffuse>
        </material>
      </visual>
      <visual name='right_inner_finger_pad_visual_1'>
        <pose>0 -0.02202 0.03242 0 -0 0</pose>
        <geometry>
          <box>
            <size>0.022 0.00635 0.0375</size>
          </box>
        </geometry>
        <material>
          <diffuse>0.9 0.9 0.9 1.0</diffuse>
        </material>
      </visual>
    </link>
    <drake:linear_bushing_rpy>
      <drake:bushing_frameA>left_inner_finger_bushing</drake:bushing_frameA>
      <drake:bushing_frameC>left_inner_knuckle_bushing</drake:bushing_frameC>
      <drake:bushing_torque_stiffness>0 15 15</drake:bushing_torque_stiffness>
      <drake:bushing_torque_damping>0 3 3</drake:bushing_torque_damping>
      <drake:bushing_force_stiffness>8000 8000 8000</drake:bushing_force_stiffness>
      <drake:bushing_force_damping>10 10 10</drake:bushing_force_damping>
    </drake:linear_bushing_rpy>
    <drake:linear_bushing_rpy>
      <drake:bushing_frameA>right_inner_finger_bushing</drake:bushing_frameA>
      <drake:bushing_frameC>right_inner_knuckle_bushing</drake:bushing_frameC>
      <drake:bushing_torque_stiffness>0 15 15</drake:bushing_torque_stiffness>
      <drake:bushing_torque_damping>0 3 3</drake:bushing_torque_damping>
      <drake:bushing_force_stiffness>8000 8000 8000</drake:bushing_force_stiffness>
      <drake:bushing_force_damping>10 10 10</drake:bushing_force_damping>
    </drake:linear_bushing_rpy>
    <drake:collision_filter_group name="left_inner_group">
      <drake:member>left_inner_knuckle</drake:member>
      <drake:member>left_inner_finger</drake:member>
      <drake:ignored_collision_filter_group>left_inner_group</drake:ignored_collision_filter_group>
    </drake:collision_filter_group>
    <drake:collision_filter_group name="right_inner_group">
      <drake:member>right_inner_knuckle</drake:member>
      <drake:member>right_inner_finger</drake:member>
      <drake:ignored_collision_filter_group>right_inner_group</drake:ignored_collision_filter_group>
    </drake:collision_filter_group>
  </model>
</sdf>