<?xml version="1.0"?>
<!-- Auto-generated from gz sdf -p GEN3_URDF_V12_with_damping.urdf -->
<sdf xmlns:drake="http://drake.mit.edu" version="1.9">
  <model name='Kinova_Gen3'>
    <link name='base_link'>
      <inertial>
        <pose>-0.000648 -0.000166 0.084487 0 -0 0</pose>
        <mass>1.697</mass>
        <inertia>
          <ixx>0.004622</ixx>
          <ixy>9e-06</ixy>
          <ixz>6e-05</ixz>
          <iyy>0.004495</iyy>
          <iyz>9e-06</iyz>
          <izz>0.002079</izz>
        </inertia>
      </inertial>
      <collision name='base_link_collision'>
        <pose>0 0 0 0 -0 0</pose>
        <geometry>
          <mesh>
            <scale>1 1 1</scale>
            <uri>../meshes/base_link.obj</uri>
          </mesh>
        </geometry>
      </collision>
      <visual name='base_link_visual'>
        <pose>0 0 0 0 -0 0</pose>
        <geometry>
          <mesh>
            <scale>1 1 1</scale>
            <uri>../meshes/base_link.obj</uri>
          </mesh>
        </geometry>
      </visual>
    </link>
    <joint name='Actuator1' type='revolute'>
      <pose relative_to='base_link'>0 0 0.15643 -3.14159 0 -0</pose>
      <parent>base_link</parent>
      <child>shoulder_link</child>
      <axis>
        <xyz>0 0 1</xyz>
        <limit>
          <effort>39</effort>
          <velocity>0.8727</velocity>
          <lower>-1e+16</lower>
          <upper>1e+16</upper>
        </limit>
        <dynamics>
          <damping>3</damping>
          <friction>0</friction>
          <spring_reference>0</spring_reference>
          <spring_stiffness>0</spring_stiffness>
        </dynamics>
      </axis>
    </joint>
    <link name='shoulder_link'>
      <pose relative_to='Actuator1'>0 0 0 0 -0 0</pose>
      <inertial>
        <pose>-2.3e-05 -0.010364 -0.07336 0 -0 0</pose>
        <mass>1.3773</mass>
        <inertia>
          <ixx>0.00457</ixx>
          <ixy>1e-06</ixy>
          <ixz>2e-06</ixz>
          <iyy>0.004831</iyy>
          <iyz>0.000448</iyz>
          <izz>0.001409</izz>
        </inertia>
      </inertial>
      <collision name='shoulder_link_collision'>
        <pose>0 0 0 0 -0 0</pose>
        <geometry>
          <mesh>
            <scale>1 1 1</scale>
            <uri>../meshes/shoulder_link.obj</uri>
          </mesh>
        </geometry>
      </collision>
      <visual name='shoulder_link_visual'>
        <pose>0 0 0 0 -0 0</pose>
        <geometry>
          <mesh>
            <scale>1 1 1</scale>
            <uri>../meshes/shoulder_link.obj</uri>
          </mesh>
        </geometry>
      </visual>
    </link>
    <joint name='Actuator2' type='revolute'>
      <pose relative_to='shoulder_link'>0 0.005375 -0.12838 1.5708 0 -0</pose>
      <parent>shoulder_link</parent>
      <child>half_arm_1_link</child>
      <axis>
        <xyz>0 0 1</xyz>
        <limit>
          <lower>-2.41</lower>
          <upper>2.41</upper>
          <effort>39</effort>
          <velocity>0.8727</velocity>
        </limit>
        <dynamics>
          <damping>3</damping>
          <friction>0</friction>
          <spring_reference>0</spring_reference>
          <spring_stiffness>0</spring_stiffness>
        </dynamics>
      </axis>
    </joint>
    <link name='half_arm_1_link'>
      <pose relative_to='Actuator2'>0 0 0 0 -0 0</pose>
      <inertial>
        <pose>-4.4e-05 -0.09958 -0.013278 0 -0 0</pose>
        <mass>1.1636</mass>
        <inertia>
          <ixx>0.011088</ixx>
          <ixy>5e-06</ixy>
          <ixz>0</ixz>
          <iyy>0.001072</iyy>
          <iyz>-0.000691</iyz>
          <izz>0.011255</izz>
        </inertia>
      </inertial>
      <collision name='half_arm_1_link_collision'>
        <pose>0 0 0 0 -0 0</pose>
        <geometry>
          <mesh>
            <scale>1 1 1</scale>
            <uri>../meshes/half_arm_1_link.obj</uri>
          </mesh>
        </geometry>
      </collision>
      <visual name='half_arm_1_link_visual'>
        <pose>0 0 0 0 -0 0</pose>
        <geometry>
          <mesh>
            <scale>1 1 1</scale>
            <uri>../meshes/half_arm_1_link.obj</uri>
          </mesh>
        </geometry>
      </visual>
    </link>
    <joint name='Actuator3' type='revolute'>
      <pose relative_to='half_arm_1_link'>0 -0.21038 -0.006375 -1.5708 0 -0</pose>
      <parent>half_arm_1_link</parent>
      <child>half_arm_2_link</child>
      <axis>
        <xyz>0 0 1</xyz>
        <limit>
          <effort>39</effort>
          <velocity>0.8727</velocity>
          <lower>-1e+16</lower>
          <upper>1e+16</upper>
        </limit>
        <dynamics>
          <damping>3</damping>
          <friction>0</friction>
          <spring_reference>0</spring_reference>
          <spring_stiffness>0</spring_stiffness>
        </dynamics>
      </axis>
    </joint>
    <link name='half_arm_2_link'>
      <pose relative_to='Actuator3'>0 0 0 0 -0 0</pose>
      <inertial>
        <pose>-4.4e-05 -0.006641 -0.117892 0 -0 0</pose>
        <mass>1.1636</mass>
        <inertia>
          <ixx>0.010932</ixx>
          <ixy>0</ixy>
          <ixz>-7e-06</ixz>
          <iyy>0.011127</iyy>
          <iyz>0.000606</iyz>
          <izz>0.001043</izz>
        </inertia>
      </inertial>
      <collision name='half_arm_2_link_collision'>
        <pose>0 0 0 0 -0 0</pose>
        <geometry>
          <mesh>
            <scale>1 1 1</scale>
            <uri>../meshes/half_arm_2_link.obj</uri>
          </mesh>
        </geometry>
      </collision>
      <visual name='half_arm_2_link_visual'>
        <pose>0 0 0 0 -0 0</pose>
        <geometry>
          <mesh>
            <scale>1 1 1</scale>
            <uri>../meshes/half_arm_2_link.obj</uri>
          </mesh>
        </geometry>
      </visual>
    </link>
    <joint name='Actuator4' type='revolute'>
      <pose relative_to='half_arm_2_link'>0 0.006375 -0.21038 1.5708 -0 -0</pose>
      <parent>half_arm_2_link</parent>
      <child>forearm_link</child>
      <axis>
        <xyz>0 0 1</xyz>
        <limit>
          <lower>-2.66</lower>
          <upper>2.66</upper>
          <effort>39</effort>
          <velocity>0.8727</velocity>
        </limit>
        <dynamics>
          <damping>3</damping>
          <friction>0</friction>
          <spring_reference>0</spring_reference>
          <spring_stiffness>0</spring_stiffness>
        </dynamics>
      </axis>
    </joint>
    <link name='forearm_link'>
      <pose relative_to='Actuator4'>0 0 0 0 -0 0</pose>
      <inertial>
        <pose>-1.8e-05 -0.075478 -0.015006 0 -0 0</pose>
        <mass>0.9302</mass>
        <inertia>
          <ixx>0.008147</ixx>
          <ixy>-1e-06</ixy>
          <ixz>0</ixz>
          <iyy>0.000631</iyy>
          <iyz>-0.0005</iyz>
          <izz>0.008316</izz>
        </inertia>
      </inertial>
      <collision name='forearm_link_collision'>
        <pose>0 0 0 0 -0 0</pose>
        <geometry>
          <mesh>
            <scale>1 1 1</scale>
            <uri>../meshes/forearm_link.obj</uri>
          </mesh>
        </geometry>
      </collision>
      <visual name='forearm_link_visual'>
        <pose>0 0 0 0 -0 0</pose>
        <geometry>
          <mesh>
            <scale>1 1 1</scale>
            <uri>../meshes/forearm_link.obj</uri>
          </mesh>
        </geometry>
      </visual>
    </link>
    <joint name='Actuator5' type='revolute'>
      <pose relative_to='forearm_link'>0 -0.20843 -0.006375 -1.5708 0 -0</pose>
      <parent>forearm_link</parent>
      <child>spherical_wrist_1_link</child>
      <axis>
        <xyz>0 0 1</xyz>
        <limit>
          <effort>9</effort>
          <velocity>0.8727</velocity>
          <lower>-1e+16</lower>
          <upper>1e+16</upper>
        </limit>
        <dynamics>
          <damping>2</damping>
          <friction>0</friction>
          <spring_reference>0</spring_reference>
          <spring_stiffness>0</spring_stiffness>
        </dynamics>
      </axis>
    </joint>
    <link name='spherical_wrist_1_link'>
      <pose relative_to='Actuator5'>0 0 0 0 -0 0</pose>
      <inertial>
        <pose>1e-06 -0.009432 -0.063883 0 -0 0</pose>
        <mass>0.6781</mass>
        <inertia>
          <ixx>0.001596</ixx>
          <ixy>0</ixy>
          <ixz>0</ixz>
          <iyy>0.001607</iyy>
          <iyz>0.000256</iyz>
          <izz>0.000399</izz>
        </inertia>
      </inertial>
      <collision name='spherical_wrist_1_link_collision'>
        <pose>0 0 0 0 -0 0</pose>
        <geometry>
          <mesh>
            <scale>1 1 1</scale>
            <uri>../meshes/spherical_wrist_1_link.obj</uri>
          </mesh>
        </geometry>
      </collision>
      <visual name='spherical_wrist_1_link_visual'>
        <pose>0 0 0 0 -0 0</pose>
        <geometry>
          <mesh>
            <scale>1 1 1</scale>
            <uri>../meshes/spherical_wrist_1_link.obj</uri>
          </mesh>
        </geometry>
      </visual>
    </link>
    <joint name='Actuator6' type='revolute'>
      <pose relative_to='spherical_wrist_1_link'>0 0.000175 -0.10593 1.5708 0 -0</pose>
      <parent>spherical_wrist_1_link</parent>
      <child>spherical_wrist_2_link</child>
      <axis>
        <xyz>0 0 1</xyz>
        <limit>
          <lower>-2.23</lower>
          <upper>2.23</upper>
          <effort>9</effort>
          <velocity>0.8727</velocity>
        </limit>
        <dynamics>
          <damping>2</damping>
          <friction>0</friction>
          <spring_reference>0</spring_reference>
          <spring_stiffness>0</spring_stiffness>
        </dynamics>
      </axis>
    </joint>
    <link name='spherical_wrist_2_link'>
      <pose relative_to='Actuator6'>0 0 0 0 -0 0</pose>
      <inertial>
        <pose>1e-06 -0.045483 -0.00965 0 -0 0</pose>
        <mass>0.6781</mass>
        <inertia>
          <ixx>0.001641</ixx>
          <ixy>0</ixy>
          <ixz>0</ixz>
          <iyy>0.00041</iyy>
          <iyz>-0.000278</iyz>
          <izz>0.001641</izz>
        </inertia>
      </inertial>
      <collision name='spherical_wrist_2_link_collision'>
        <pose>0 0 0 0 -0 0</pose>
        <geometry>
          <mesh>
            <scale>1 1 1</scale>
            <uri>../meshes/spherical_wrist_2_link.obj</uri>
          </mesh>
        </geometry>
      </collision>
      <visual name='spherical_wrist_2_link_visual'>
        <pose>0 0 0 0 -0 0</pose>
        <geometry>
          <mesh>
            <scale>1 1 1</scale>
            <uri>../meshes/spherical_wrist_2_link.obj</uri>
          </mesh>
        </geometry>
      </visual>
    </link>
    <joint name='Actuator7' type='revolute'>
      <pose relative_to='spherical_wrist_2_link'>0 -0.10593 -0.000175 -1.5708 -0 0</pose>
      <parent>spherical_wrist_2_link</parent>
      <child>bracelet_no_vision_link</child>
      <axis>
        <xyz>0 0 1</xyz>
        <limit>
          <effort>9</effort>
          <velocity>0.8727</velocity>
          <lower>-1e+16</lower>
          <upper>1e+16</upper>
        </limit>
        <dynamics>
          <damping>2</damping>
          <friction>0</friction>
          <spring_reference>0</spring_reference>
          <spring_stiffness>0</spring_stiffness>
        </dynamics>
      </axis>
    </joint>
    <link name='bracelet_no_vision_link'>
      <pose relative_to='Actuator7'>0 0 0 0 -0 0</pose>
      <inertial>
        <pose>-0.000281 -0.011402 -0.029798 0 -0 0</pose>
        <mass>0.5006</mass>
        <inertia>
          <ixx>0.000587</ixx>
          <ixy>3e-06</ixy>
          <ixz>3e-06</ixz>
          <iyy>0.000369</iyy>
          <iyz>0.000118</iyz>
          <izz>0.000609</izz>
        </inertia>
      </inertial>
      <collision name='bracelet_no_vision_link_collision'>
        <pose>0 0 0 0 -0 0</pose>
        <geometry>
          <mesh>
            <scale>1 1 1</scale>
            <uri>../meshes/bracelet_no_vision_link.obj</uri>
          </mesh>
        </geometry>
      </collision>
      <visual name='bracelet_no_vision_link_visual'>
        <pose>0 0 0 0 -0 0</pose>
        <geometry>
          <mesh>
            <scale>1 1 1</scale>
            <uri>../meshes/bracelet_no_vision_link.obj</uri>
          </mesh>
        </geometry>
      </visual>
    </link>
  </model>
</sdf>
